[32m2024-07-26 14:54:12 +0100[0m - dagster - [34mDEBUG[0m - __ASSET_JOB - 80988480-c3ea-4eda-9f49-410bfee5cbde - 20837 - LOGS_CAPTURED - Started capturing logs in process (pid: 20837).
[32m2024-07-26 14:54:12 +0100[0m - dagster - [34mDEBUG[0m - __ASSET_JOB - 80988480-c3ea-4eda-9f49-410bfee5cbde - 20837 - taxi_zones - STEP_START - Started execution of step "taxi_zones".
[32m2024-07-26 14:54:12 +0100[0m - dagster - [34mERROR[0m - [31m__ASSET_JOB - 80988480-c3ea-4eda-9f49-410bfee5cbde - 20837 - taxi_zones - STEP_FAILURE - Execution of step "taxi_zones" failed.

dagster._core.errors.DagsterExecutionStepExecutionError: Error occurred while executing op "taxi_zones"::

NameError: name 'os' is not defined

Stack Trace:
  File "/Users/millwn04/.virtualenv/dagster-training-3.11/lib/python3.11/site-packages/dagster/_core/execution/plan/utils.py", line 54, in op_execution_error_boundary
    yield
  File "/Users/millwn04/.virtualenv/dagster-training-3.11/lib/python3.11/site-packages/dagster/_utils/__init__.py", line 473, in iterate_with_context
    next_output = next(iterator)
                  ^^^^^^^^^^^^^^
  File "/Users/millwn04/.virtualenv/dagster-training-3.11/lib/python3.11/site-packages/dagster/_core/execution/plan/compute_generator.py", line 141, in _coerce_op_compute_fn_to_iterator
    result = invoke_compute_fn(
             ^^^^^^^^^^^^^^^^^^
  File "/Users/millwn04/.virtualenv/dagster-training-3.11/lib/python3.11/site-packages/dagster/_core/execution/plan/compute_generator.py", line 129, in invoke_compute_fn
    return fn(context, **args_to_pass) if context_arg_provided else fn(**args_to_pass)
                                                                    ^^^^^^^^^^^^^^^^^^
  File "/Users/millwn04/development/training/learning-and-innovation/dagster_university/dagster_university/assets/trips.py", line 77, in taxi_zones
    conn = duckdb.connect(os.getenv("DUCKDB_DATABASE"))
                          ^^
[0m
